Workbook

Sheet Cover
B2: Sukuk Expected Credit Loss (ECL) Model
B3: IFRS 9 / AAOIFI FAS 30 three-stage impairment model for a sukuk investment portfolio
B5: WORKBOOK MAP
B6: Cover | C6: This sheet: purpose, legend, methodology and limitations.
B7: Assumptions | C7: Reporting date, staging (SICR) thresholds, macro-economic scenarios & weights, rating-to-PD table, LGD by sukuk structure.
B8: Portfolio | C8: One row per sukuk holding (capacity 50 rows). Enter holdings in the blue/yellow columns A:P; columns Q:Z calculate automatically.
B9: ECL_Calc | C9: Per-sukuk, per-scenario PD, LGD, 12-month and lifetime ECL, then probability-weighted ECL. No inputs.
B10: Summary | C10: ECL by stage, by sukuk structure, by accounting classification, scenario sensitivity and model integrity checks.
B11: Check_Schedule | C11: Year-by-year lifetime ECL build-up for one selected sukuk, reconciling to the closed-form result in ECL_Calc.
B13: COLOUR LEGEND
B14: Blue text | C14: Hard-coded input - edit these.
B15: Yellow fill | C15: Key assumption / cell the user should review or fill in.
B16: Black text | C16: Formula - do not overwrite.
B17: Green text | C17: Link pulled from another sheet.
B19: METHODOLOGY
B20: ECL formula | C20: ECL = Σ over scenarios [ weight_s × Σ over years t ( Marginal PD_s,t × LGD_s × EAD × DF_t ) ]. EAD = gross carrying amount + accrued profit (bullet sukuk assumed; EAD held flat to maturity).
B21: Staging | C21: Stage 3 (credit-impaired): DPD > Stage-3 backstop, current rating 'D', or credit-impaired flag = Y. Stage 2 (SICR): DPD > Stage-2 backstop, watchlist = Y, or rating downgraded by ≥ the notch threshold since origination. If the low-credit-risk (LCR) exemption is ON, a downgrade alone does not trigger Stage 2 while the current rating is at or above the LCR threshold (investment grade). DPD/watchlist backstops still apply. Stage 1: all others. A manual stage override (column O of Portfolio) takes precedence and must be documented.
B22: Measurement | C22: Stage 1 = 12-month ECL. Stage 2 = lifetime ECL to contractual maturity. Stage 3 = EAD × LGD (PD = 100%).
B23: PD | C23: Through-the-cycle 12-month PD from the current external/internal rating (Assumptions table). Converted to point-in-time per scenario with a PD multiplier and capped. Lifetime PD assumes a constant annual hazard: cumulative PD(t) = 1 − (1 − PD)^t; the final partial year is pro-rated on a hazard basis.
B24: LGD | C24: Set by sukuk structure: asset-backed structures (true sale, recourse to the underlying asset) carry lower LGD than asset-based structures (recourse to the obligor / purchase undertaking only). Mudaraba / Musharaka are equity-like (loss-sharing) and carry higher LGD. Per-scenario LGD multipliers capture forward-looking collateral value. A per-sukuk LGD override is available.
B25: Discounting | C25: Losses are discounted at each sukuk's effective profit rate (EIR), consistent with IFRS 9 B5.5.44.
B26: Forward-looking | C26: Three probability-weighted scenarios (Base / Upside / Downside). ECL is computed in full under each scenario and then weighted (not computed on a weighted PD), so non-linearity is captured.
B27: FVOCI sukuk | C27: For sukuk at FVOCI the allowance is recognised in OCI and does not reduce the carrying amount in the balance sheet; the ECL charge still goes to P&L. Summary splits AC vs FVOCI.
B29: LIMITATIONS
B30: Illustrative inputs | C30: All PDs, LGDs, scenario weights/multipliers and the sample portfolio are ILLUSTRATIVE placeholders, not calibrated figures. Replace them with the institution's approved, calibrated parameters (e.g. rating-agency default studies, internal default history, macro-economic satellite models) before use.
B31: Simplifications | C31: Bullet repayment (flat EAD); constant hazard rate per rating; scenario multipliers applied uniformly across the term; no amortising/sinking-fund profiles; no prepayment. Extend ECL_Calc if the portfolio has amortising sukuk.
B32: Governance | C32: Results should be reviewed against Shariah and credit committee policies and validated independently before booking.

Sheet Assumptions
B1: Model Assumptions
B2: General & staging parameters
B3: Reporting date | C3: 46295 | F3: Input: period-end reporting date.
B4: Presentation currency | C4: USD | F4: Input: all amounts in this currency (units).
B5: SICR: downgrade threshold (notches) | C5: 3 | F5: Policy assumption: downgrade of ≥3 notches since origination = significant increase in credit risk. Align to approved IFRS 9 policy.
B6: Stage 2 DPD backstop (days) | C6: 30 | F6: IFRS 9 5.5.11 rebuttable presumption: >30 days past due.
B7: Stage 3 DPD backstop (days) | C7: 90 | F7: IFRS 9 B5.5.37 rebuttable presumption: >90 days past due = default.
B8: Apply low-credit-risk exemption (Y/N) | C8: Y | F8: IFRS 9 5.5.10: instruments with low credit risk (typically investment grade) may be kept in Stage 1.
B9: LCR threshold rating (lowest qualifying) | C9: BBB- | F9: Lowest rating treated as 'low credit risk'.
B10: PD cap | C10: 0.9999 | F10: Technical cap to keep lifetime formulas defined; Stage 3 uses PD = 100% separately.
B11: Days per year | C11: 365.25 | F11: Day-count basis for remaining term.
B13: Macro-economic scenarios (forward-looking information)
B14: Scenario | C14: Weight | D14: PD multiplier | E14: LGD multiplier | F14: Note
B15: Base | C15: 0.5 | D15: 1 | E15: 1 | F15: Illustrative - replace with output of macro-economic satellite model (GDP, oil price, CDS spreads).
B16: Upside | C16: 0.2 | D16: 0.8 | E16: 0.95 | F16: Illustrative - replace with output of macro-economic satellite model (GDP, oil price, CDS spreads).
B17: Downside | C17: 0.3 | D17: 1.6 | E17: 1.15 | F17: Illustrative - replace with output of macro-economic satellite model (GDP, oil price, CDS spreads).
B18: Total weight (must = 100%) | C18: =SUM(C15:C17) -> 1 | D18: =IF(ROUND(C18,6)=1,"OK","ERROR") -> OK
B21: Rating master scale - 12-month through-the-cycle PD
B22: Rating | C22: Notch index | D22: 12m PD (TTC) | E22: Investment grade? | F22: Source / note
B23: AAA | C23: =ROW()-22 -> 1 | D23: 0.0001 | E23: =IF(C23<=MATCH($C$9,$B$23:$B$40,0),"Yes","No") -> Yes | F23: Illustrative long-run average; calibrate to agency default studies / internal data.
B24: AA+ | C24: =ROW()-22 -> 2 | D24: 0.0002 | E24: =IF(C24<=MATCH($C$9,$B$23:$B$40,0),"Yes","No") -> Yes | F24: Illustrative
B25: AA | C25: =ROW()-22 -> 3 | D25: 0.0002 | E25: =IF(C25<=MATCH($C$9,$B$23:$B$40,0),"Yes","No") -> Yes | F25: Illustrative
B26: AA- | C26: =ROW()-22 -> 4 | D26: 0.0003 | E26: =IF(C26<=MATCH($C$9,$B$23:$B$40,0),"Yes","No") -> Yes | F26: Illustrative
B27: A+ | C27: =ROW()-22 -> 5 | D27: 0.0004 | E27: =IF(C27<=MATCH($C$9,$B$23:$B$40,0),"Yes","No") -> Yes | F27: Illustrative
B28: A | C28: =ROW()-22 -> 6 | D28: 0.0005 | E28: =IF(C28<=MATCH($C$9,$B$23:$B$40,0),"Yes","No") -> Yes | F28: Illustrative
B29: A- | C29: =ROW()-22 -> 7 | D29: 0.0007 | E29: =IF(C29<=MATCH($C$9,$B$23:$B$40,0),"Yes","No") -> Yes | F29: Illustrative
B30: BBB+ | C30: =ROW()-22 -> 8 | D30: 0.001 | E30: =IF(C30<=MATCH($C$9,$B$23:$B$40,0),"Yes","No") -> Yes | F30: Illustrative
B31: BBB | C31: =ROW()-22 -> 9 | D31: 0.0015 | E31: =IF(C31<=MATCH($C$9,$B$23:$B$40,0),"Yes","No") -> Yes | F31: Illustrative
B32: BBB- | C32: =ROW()-22 -> 10 | D32: 0.0025 | E32: =IF(C32<=MATCH($C$9,$B$23:$B$40,0),"Yes","No") -> Yes | F32: Illustrative
B33: BB+ | C33: =ROW()-22 -> 11 | D33: 0.0035 | E33: =IF(C33<=MATCH($C$9,$B$23:$B$40,0),"Yes","No") -> No | F33: Illustrative
B34: BB | C34: =ROW()-22 -> 12 | D34: 0.0055 | E34: =IF(C34<=MATCH($C$9,$B$23:$B$40,0),"Yes","No") -> No | F34: Illustrative
... B40: D | C40: =ROW()-22 -> 18 | D40: 1 | E40: =IF(C40<=MATCH($C$9,$B$23:$B$40,0),"Yes","No") -> No | F40: Illustrative
B43: Loss Given Default by sukuk structure
B44: Structure | C44: LGD | D44: Recourse type | F44: Rationale
B45: Sovereign | C45: 0.4 | D45: Sovereign obligor | F45: Sovereign / quasi-sovereign sukuk; recovery driven by restructuring outcomes. Illustrative.
B46: Ijara (asset-backed) | C46: 0.35 | D46: Asset | F46: True sale of leased asset to SPV; holders have recourse to the asset. Illustrative.
B47: Ijara (asset-based) | C47: 0.45 | D47: Obligor | F47: Beneficial ownership only; recourse via purchase undertaking - senior unsecured equivalent. Illustrative.
B48: Wakala | C48: 0.45 | D48: Obligor | F48: Pool of assets managed by wakeel; typically asset-based with purchase undertaking. Illustrative.
B49: Murabaha | C49: 0.45 | D49: Obligor | F49: Receivable / commodity murabaha; unsecured claim on obligor. Illustrative.
B50: Mudaraba | C50: 0.6 | D50: Profit & loss sharing | F50: Equity-like; capital at risk of the venture. Illustrative.
...

Sheet Portfolio
A1: Sukuk Portfolio - holdings & staging
A2: Enter holdings in columns A:P (blue = input). Rows 6-13 are ILLUSTRATIVE sample holdings - overwrite or delete them. Columns Q:Z are formulas.
A3: Reporting date: | C3: =Assumptions!C3 -> 46295
A5: Sukuk ID | B5: Issuer | C5: ISIN | D5: Structure | E5: Classification (AC / FVOCI) | F5: Gross carrying amount | G5: Accrued profit | H5: Effective profit rate (EIR) | I5: Maturity date | J5: Rating at origination | K5: Current rating | L5: Days past due | M5: Watchlist (Y/N) | N5: Credit-impaired (Y/N) | O5: Stage override (1/2/3) | P5: LGD override | Q5: EAD | R5: Remaining term (yrs) | S5: Orig. notch | T5: Current notch | U5: Notches downgraded | V5: Model stage | W5: Final stage | X5: 12m PD (TTC) | Y5: LGD (base) | Z5: ECL (weighted)
A6: SK-001 | B6: Sample Sovereign A | C6: XS0000000001 | D6: Sovereign | E6: AC | F6: 10000000 | G6: 125000 | H6: 0.0475 | I6: 48014 | J6: A+ | K6: A+ | L6: 0 | M6: N | N6: N | Q6: =IF($A6="","",F6+G6) -> 10125000 | R6: =IF($A6="","",MAX(0,(I6-Assumptions!$C$3)/Assumptions!$C$11)) -> 4.7063655 | S6: =IF($A6="","",MATCH(J6,Assumptions!$B$23:$B$40,0)) -> 5 | T6: =IF($A6="","",MATCH(K6,Assumptions!$B$23:$B$40,0)) -> 5 | U6: =IF($A6="","",T6-S6) -> 0 | V6: =IF($A6="","",IF(OR(L6>Assumptions!$C$7,K6="D",N6="Y"),3,IF(OR(L6>Assumptions!$C$6,M6="Y",AND(U6>=Assumptions!$C$5,NOT(AND(Assumptions!$C$8="Y",T6<=MATCH(Assumptions!$C$9,Assumptions!$B$23:$B$40,0))))),2,1))) -> 1 | W6: =IF($A6="","",IF(O6="",V6,O6)) -> 1 | X6: =IF($A6="","",INDEX(Assumptions!$D$23:$D$40,T6)) -> 0.0004 | Y6: =IF($A6="","",IF(P6="",INDEX(Assumptions!$C$45:$C$51,MATCH(D6,Assumptions!$B$45:$B$51,0)),P6)) -> 0.4 | Z6: =IF($A6="","",ECL_Calc!AA6) -> 1862.0334
A7: SK-002 | B7: Sample Bank B | C7: XS0000000002 | D7: Wakala | E7: FVOCI | F7: 5000000 | G7: 42000 | H7: 0.052 | I7: 47178 | J7: A- | K7: BBB | L7: 0 | M7: N | N7: N | Q7: =IF($A7="","",F7+G7) -> 5042000 | R7: =IF($A7="","",MAX(0,(I7-Assumptions!$C$3)/Assumptions!$C$11)) -> 2.4175222 | S7: =IF($A7="","",MATCH(J7,Assumptions!$B$23:$B$40,0)) -> 7 | T7: =IF($A7="","",MATCH(K7,Assumptions!$B$23:$B$40,0)) -> 9 | U7: =IF($A7="","",T7-S7) -> 2 | V7: =IF($A7="","",IF(OR(L7>Assumptions!$C$7,K7="D",N7="Y"),3,IF(OR(L7>Assumptions!$C$6,M7="Y",AND(U7>=Assumptions!$C$5,NOT(AND(Assumptions!$C$8="Y",T7<=MATCH(Assumptions!$C$9,Assumptions!$B$23:$B$40,0))))),2,1))) -> 1 | W7: =IF($A7="","",IF(O7="",V7,O7)) -> 1 | X7: =IF($A7="","",INDEX(Assumptions!$D$23:$D$40,T7)) -> 0.0015 | Y7: =IF($A7="","",IF(P7="",INDEX(Assumptions!$C$45:$C$51,MATCH(D7,Assumptions!$B$45:$B$51,0)),P7)) -> 0.45 | Z7: =IF($A7="","",ECL_Calc!AA7) -> 3895.0888
A8: SK-003 | B8: Sample Real Estate C | C8: XS0000000003 | D8: Ijara (asset-backed) | E8: AC | F8: 7500000 | G8: 90000 | H8: 0.061 | I8: 47807 | J8: BBB | K8: BB | L8: 0 | M8: N | N8: N | Q8: =IF($A8="","",F8+G8) -> 7590000 | R8: =IF($A8="","",MAX(0,(I8-Assumptions!$C$3)/Assumptions!$C$11)) -> 4.1396304 | S8: =IF($A8="","",MATCH(J8,Assumptions!$B$23:$B$40,0)) -> 9 | T8: =IF($A8="","",MATCH(K8,Assumptions!$B$23:$B$40,0)) -> 12 | U8: =IF($A8="","",T8-S8) -> 3 | V8: =IF($A8="","",IF(OR(L8>Assumptions!$C$7,K8="D",N8="Y"),3,IF(OR(L8>Assumptions!$C$6,M8="Y",AND(U8>=Assumptions!$C$5,NOT(AND(Assumptions!$C$8="Y",T8<=MATCH(Assumptions!$C$9,Assumptions!$B$23:$B$40,0))))),2,1))) -> 2 | W8: =IF($A8="","",IF(O8="",V8,O8)) -> 2 | X8: =IF($A8="","",INDEX(Assumptions!$D$23:$D$40,T8)) -> 0.0055 | Y8: =IF($A8="","",IF(P8="",INDEX(Assumptions!$C$45:$C$51,MATCH(D8,Assumptions!$B$45:$B$51,0)),P8)) -> 0.35 | Z8: =IF($A8="","",ECL_Calc!AA8) -> 62098.8
A9: SK-004 | B9: Sample Telecom D | C9: XS0000000004 | D9: Murabaha | E9: AC | F9: 3000000 | G9: 15500 | H9: 0.056 | I9: 46507 | J9: BBB+ | K9: BBB+ | L9: 0 | M9: N | N9: N | Q9: =IF($A9="","",F9+G9) -> 3015500 | R9: =IF($A9="","",MAX(0,(I9-Assumptions!$C$3)/Assumptions!$C$11)) -> 0.58042437 | S9: =IF($A9="","",MATCH(J9,Assumptions!$B$23:$B$40,0)) -> 8 | T9: =IF($A9="","",MATCH(K9,Assumptions!$B$23:$B$40,0)) -> 8 | U9: =IF($A9="","",T9-S9) -> 0 | V9: =IF($A9="","",IF(OR(L9>Assumptions!$C$7,K9="D",N9="Y"),3,IF(OR(L9>Assumptions!$C$6,M9="Y",AND(U9>=Assumptions!$C$5,NOT(AND(Assumptions!$C$8="Y",T9<=MATCH(Assumptions!$C$9,Assumptions!$B$23:$B$40,0))))),2,1))) -> 1 | W9: =IF($A9="","",IF(O9="",V9,O9)) -> 1 | X9: =IF($A9="","",INDEX(Assumptions!$D$23:$D$40,T9)) -> 0.001 | Y9: =IF($A9="","",IF(P9="",INDEX(Assumptions!$C$45:$C$51,MATCH(D9,Assumptions!$B$45:$B$51,0)),P9)) -> 0.45 | Z9: =IF($A9="","",ECL_Calc!AA9) -> 919.01539
A10: SK-005 | B10: Sample Utility E | C10: XS0000000005 | D10: Ijara (asset-based) | E10: FVOCI | F10: 4000000 | G10: 38000 | H10: 0.059 | I10: 48832 | J10: BBB- | K10: BBB- | L10: 45 | M10: N | N10: N | Q10: =IF($A10="","",F10+G10) -> 4038000 | R10: =IF($A10="","",MAX(0,(I10-Assumptions!$C$3)/Assumptions!$C$11)) -> 6.9459274 | S10: =IF($A10="","",MATCH(J10,Assumptions!$B$23:$B$40,0)) -> 10 | T10: =IF($A10="","",MATCH(K10,Assumptions!$B$23:$B$40,0)) -> 10 | U10: =IF($A10="","",T10-S10) -> 0 | V10: =IF($A10="","",IF(OR(L10>Assumptions!$C$7,K10="D",N10="Y"),3,IF(OR(L10>Assumptions!$C$6,M10="Y",AND(U10>=Assumptions!$C$5,NOT(AND(Assumptions!$C$8="Y",T10<=MATCH(Assumptions!$C$9,Assumptions!$B$23:$B$40,0))))),2,1))) -> 2 | W10: =IF($A10="","",IF(O10="",V10,O10)) -> 2 | X10: =IF($A10="","",INDEX(Assumptions!$D$23:$D$40,T10)) -> 0.0025 | Y10: =IF($A10="","",IF(P10="",INDEX(Assumptions!$C$45:$C$51,MATCH(D10,Assumptions!$B$45:$B$51,0)),P10)) -> 0.45 | Z10: =IF($A10="","",ECL_Calc!AA10) -> 30194.106
A11: SK-006 | B11: Sample Developer F | C11: XS0000000006 | D11: Musharaka | E11: AC | F11: 2000000 | G11: 60000 | H11: 0.085 | I11: 46811 | J11: BB | K11: B- | L11: 0 | M11: Y | N11: N | Q11: =IF($A11="","",F11+G11) -> 2060000 | R11: =IF($A11="","",MAX(0,(I11-Assumptions!$C$3)/Assumptions!$C$11)) -> 1.412731 | S11: =IF($A11="","",MATCH(J11,Assumptions!$B$23:$B$40,0)) -> 12 | T11: =IF($A11="","",MATCH(K11,Assumptions!$B$23:$B$40,0)) -> 16 | U11: =IF($A11="","",T11-S11) -> 4 | V11: =IF($A11="","",IF(OR(L11>Assumptions!$C$7,K11="D",N11="Y"),3,IF(OR(L11>Assumptions!$C$6,M11="Y",AND(U11>=Assumptions!$C$5,NOT(AND(Assumptions!$C$8="Y",T11<=MATCH(Assumptions!$C$9,Assumptions!$B$23:$B$40,0))))),2,1))) -> 2 | W11: =IF($A11="","",IF(O11="",V11,O11)) -> 2 | X11: =IF($A11="","",INDEX(Assumptions!$D$23:$D$40,T11)) -> 0.05 | Y11: =IF($A11="","",IF(P11="",INDEX(Assumptions!$C$45:$C$51,MATCH(D11,Assumptions!$B$45:$B$51,0)),P11)) -> 0.6 | Z11: =IF($A11="","",ECL_Calc!AA11) -> 94720.905
A12: SK-007 | B12: Sample Airline G | C12: XS0000000007 | D12: Mudaraba | E12: AC | F12: 1500000 | G12: 70000 | H12: 0.09 | I12: 46752 | J12: BB- | K12: D | L12: 120 | M12: N | N12: Y | Q12: =IF($A12="","",F12+G12) -> 1570000 | R12: =IF($A12="","",MAX(0,(I12-Assumptions!$C$3)/Assumptions!$C$11)) -> 1.2511978 | S12: =IF($A12="","",MATCH(J12,Assumptions!$B$23:$B$40,0)) -> 13 | T12: =IF($A12="","",MATCH(K12,Assumptions!$B$23:$B$40,0)) -> 18 | U12: =IF($A12="","",T12-S12) -> 5 | V12: =IF($A12="","",IF(OR(L12>Assumptions!$C$7,K12="D",N12="Y"),3,IF(OR(L12>Assumptions!$C$6,M12="Y",AND(U12>=Assumptions!$C$5,NOT(AND(Assumptions!$C$8="Y",T12<=MATCH(Assumptions!$C$9,Assumptions!$B$23:$B$40,0))))),2,1))) -> 3 | W12: =IF($A12="","",IF(O12="",V12,O12)) -> 3 | X12: =IF($A12="","",INDEX(Assumptions!$D$23:$D$40,T12)) -> 1 | Y12: =IF($A12="","",IF(P12="",INDEX(Assumptions!$C$45:$C$51,MATCH(D12,Assumptions!$B$45:$B$51,0)),P12)) -> 0.6 | Z12: =IF($A12="","",ECL_Calc!AA12) -> 974970
A13: SK-008 | B13: Sample GRE H | C13: XS0000000008 | D13: Sovereign | E13: AC | F13: 8000000 | G13: 64000 | H13: 0.043 | I13: 49689 | J13: AA- | K13: AA- | L13: 0 | M13: N | N13: N | Q13: =IF($A13="","",F13+G13) -> 8064000 | R13: =IF($A13="","",MAX(0,(I13-Assumptions!$C$3)/Assumptions!$C$11)) -> 9.2922656 | S13: =IF($A13="","",MATCH(J13,Assumptions!$B$23:$B$40,0)) -> 4 | T13: =IF($A13="","",MATCH(K13,Assumptions!$B$23:$B$40,0)) -> 4 | U13: =IF($A13="","",T13-S13) -> 0 | V13: =IF($A13="","",IF(OR(L13>Assumptions!$C$7,K13="D",N13="Y"),3,IF(OR(L13>Assumptions!$C$6,M13="Y",AND(U13>=Assumptions!$C$5,NOT(AND(Assumptions!$C$8="Y",T13<=MATCH(Assumptions!$C$9,Assumptions!$B$23:$B$40,0))))),2,1))) -> 1 | W13: =IF($A13="","",IF(O13="",V13,O13)) -> 1 | X13: =IF($A13="","",INDEX(Assumptions!$D$23:$D$40,T13)) -> 0.0003 | Y13: =IF($A13="","",IF(P13="",INDEX(Assumptions!$C$45:$C$51,MATCH(D13,Assumptions!$B$45:$B$51,0)),P13)) -> 0.4 | Z13: =IF($A13="","",ECL_Calc!AA13) -> 1117.0534
Q14: =IF($A14="","",F14+G14) | R14: =IF($A14="","",MAX(0,(I14-Assumptions!$C$3)/Assumptions!$C$11)) | S14: =IF($A14="","",MATCH(J14,Assumptions!$B$23:$B$40,0)) | T14: =IF($A14="","",MATCH(K14,Assumptions!$B$23:$B$40,0)) | U14: =IF($A14="","",T14-S14) | V14: =IF($A14="","",IF(OR(L14>Assumptions!$C$7,K14="D",N14="Y"),3,IF(OR(L14>Assumptions!$C$6,M14="Y",AND(U14>=Assumptions!$C$5,NOT(AND(Assumptions!$C$8="Y",T14<=MATCH(Assumptions!$C$9,Assumptions!$B$23:$B$40,0))))),2,1))) | W14: =IF($A14="","",IF(O14="",V14,O14)) | X14: =IF($A14="","",INDEX(Assumptions!$D$23:$D$40,T14)) | Y14: =IF($A14="","",IF(P14="",INDEX(Assumptions!$C$45:$C$51,MATCH(D14,Assumptions!$B$45:$B$51,0)),P14)) | Z14: =IF($A14="","",ECL_Calc!AA14)
Q15: =IF($A15="","",F15+G15) | R15: =IF($A15="","",MAX(0,(I15-Assumptions!$C$3)/Assumptions!$C$11)) | S15: =IF($A15="","",MATCH(J15,Assumptions!$B$23:$B$40,0)) | T15: =IF($A15="","",MATCH(K15,Assumptions!$B$23:$B$40,0)) | U15: =IF($A15="","",T15-S15) | V15: =IF($A15="","",IF(OR(L15>Assumptions!$C$7,K15="D",N15="Y"),3,IF(OR(L15>Assumptions!$C$6,M15="Y",AND(U15>=Assumptions!$C$5,NOT(AND(Assumptions!$C$8="Y",T15<=MATCH(Assumptions!$C$9,Assumptions!$B$23:$B$40,0))))),2,1))) | W15: =IF($A15="","",IF(O15="",V15,O15)) | X15: =IF($A15="","",INDEX(Assumptions!$D$23:$D$40,T15)) | Y15: =IF($A15="","",IF(P15="",INDEX(Assumptions!$C$45:$C$51,MATCH(D15,Assumptions!$B$45:$B$51,0)),P15)) | Z15: =IF($A15="","",ECL_Calc!AA15)
Q16: =IF($A16="","",F16+G16) | R16: =IF($A16="","",MAX(0,(I16-Assumptions!$C$3)/Assumptions!$C$11)) | S16: =IF($A16="","",MATCH(J16,Assumptions!$B$23:$B$40,0)) | T16: =IF($A16="","",MATCH(K16,Assumptions!$B$23:$B$40,0)) | U16: =IF($A16="","",T16-S16) | V16: =IF($A16="","",IF(OR(L16>Assumptions!$C$7,K16="D",N16="Y"),3,IF(OR(L16>Assumptions!$C$6,M16="Y",AND(U16>=Assumptions!$C$5,NOT(AND(Assumptions!$C$8="Y",T16<=MATCH(Assumptions!$C$9,Assumptions!$B$23:$B$40,0))))),2,1))) | W16: =IF($A16="","",IF(O16="",V16,O16)) | X16: =IF($A16="","",INDEX(Assumptions!$D$23:$D$40,T16)) | Y16: =IF($A16="","",IF(P16="",INDEX(Assumptions!$C$45:$C$51,MATCH(D16,Assumptions!$B$45:$B$51,0)),P16)) | Z16: =IF($A16="","",ECL_Calc!AA16)
Q17: =IF($A17="","",F17+G17) | R17: =IF($A17="","",MAX(0,(I17-Assumptions!$C$3)/Assumptions!$C$11)) | S17: =IF($A17="","",MATCH(J17,Assumptions!$B$23:$B$40,0)) | T17: =IF($A17="","",MATCH(K17,Assumptions!$B$23:$B$40,0)) | U17: =IF($A17="","",T17-S17) | V17: =IF($A17="","",IF(OR(L17>Assumptions!$C$7,K17="D",N17="Y"),3,IF(OR(L17>Assumptions!$C$6,M17="Y",AND(U17>=Assumptions!$C$5,NOT(AND(Assumptions!$C$8="Y",T17<=MATCH(Assumptions!$C$9,Assumptions!$B$23:$B$40,0))))),2,1))) | W17: =IF($A17="","",IF(O17="",V17,O17)) | X17: =IF($A17="","",INDEX(Assumptions!$D$23:$D$40,T17)) | Y17: =IF($A17="","",IF(P17="",INDEX(Assumptions!$C$45:$C$51,MATCH(D17,Assumptions!$B$45:$B$51,0)),P17)) | Z17: =IF($A17="","",ECL_Calc!AA17)
Q18: =IF($A18="","",F18+G18) | R18: =IF($A18="","",MAX(0,(I18-Assumptions!$C$3)/Assumptions!$C$11)) | S18: =IF($A18="","",MATCH(J18,Assumptions!$B$23:$B$40,0)) | T18: =IF($A18="","",MATCH(K18,Assumptions!$B$23:$B$40,0)) | U18: =IF($A18="","",T18-S18) | V18: =IF($A18="","",IF(OR(L18>Assumptions!$C$7,K18="D",N18="Y"),3,IF(OR(L18>Assumptions!$C$6,M18="Y",AND(U18>=Assumptions!$C$5,NOT(AND(Assumptions!$C$8="Y",T18<=MATCH(Assumptions!$C$9,Assumptions!$B$23:$B$40,0))))),2,1))) | W18: =IF($A18="","",IF(O18="",V18,O18)) | X18: =IF($A18="","",INDEX(Assumptions!$D$23:$D$40,T18)) | Y18: =IF($A18="","",IF(P18="",INDEX(Assumptions!$C$45:$C$51,MATCH(D18,Assumptions!$B$45:$B$51,0)),P18)) | Z18: =IF($A18="","",ECL_Calc!AA18)
Q19: =IF($A19="","",F19+G19) | R19: =IF($A19="","",MAX(0,(I19-Assumptions!$C$3)/Assumptions!$C$11)) | S19: =IF($A19="","",MATCH(J19,Assumptions!$B$23:$B$40,0)) | T19: =IF($A19="","",MATCH(K19,Assumptions!$B$23:$B$40,0)) | U19: =IF($A19="","",T19-S19) | V19: =IF($A19="","",IF(OR(L19>Assumptions!$C$7,K19="D",N19="Y"),3,IF(OR(L19>Assumptions!$C$6,M19="Y",AND(U19>=Assumptions!$C$5,NOT(AND(Assumptions!$C$8="Y",T19<=MATCH(Assumptions!$C$9,Assumptions!$B$23:$B$40,0))))),2,1))) | W19: =IF($A19="","",IF(O19="",V19,O19)) | X19: =IF($A19="","",INDEX(Assumptions!$D$23:$D$40,T19)) | Y19: =IF($A19="","",IF(P19="",INDEX(Assumptions!$C$45:$C$51,MATCH(D19,Assumptions!$B$45:$B$51,0)),P19)) | Z19: =IF($A19="","",ECL_Calc!AA19)
Q20: =IF($A20="","",F20+G20) | R20: =IF($A20="","",MAX(0,(I20-Assumptions!$C$3)/Assumptions!$C$11)) | S20: =IF($A20="","",MATCH(J20,Assumptions!$B$23:$B$40,0)) | T20: =IF($A20="","",MATCH(K20,Assumptions!$B$23:$B$40,0)) | U20: =IF($A20="","",T20-S20) | V20: =IF($A20="","",IF(OR(L20>Assumptions!$C$7,K20="D",N20="Y"),3,IF(OR(L20>Assumptions!$C$6,M20="Y",AND(U20>=Assumptions!$C$5,NOT(AND(Assumptions!$C$8="Y",T20<=MATCH(Assumptions!$C$9,Assumptions!$B$23:$B$40,0))))),2,1))) | W20: =IF($A20="","",IF(O20="",V20,O20)) | X20: =IF($A20="","",INDEX(Assumptions!$D$23:$D$40,T20)) | Y20: =IF($A20="","",IF(P20="",INDEX(Assumptions!$C$45:$C$51,MATCH(D20,Assumptions!$B$45:$B$51,0)),P20)) | Z20: =IF($A20="","",ECL_Calc!AA20)
Q21: =IF($A21="","",F21+G21) | R21: =IF($A21="","",MAX(0,(I21-Assumptions!$C$3)/Assumptions!$C$11)) | S21: =IF($A21="","",MATCH(J21,Assumptions!$B$23:$B$40,0)) | T21: =IF($A21="","",MATCH(K21,Assumptions!$B$23:$B$40,0)) | U21: =IF($A21="","",T21-S21) | V21: =IF($A21="","",IF(OR(L21>Assumptions!$C$7,K21="D",N21="Y"),3,IF(OR(L21>Assumptions!$C$6,M21="Y",AND(U21>=Assumptions!$C$5,NOT(AND(Assumptions!$C$8="Y",T21<=MATCH(Assumptions!$C$9,Assumptions!$B$23:$B$40,0))))),2,1))) | W21: =IF($A21="","",IF(O21="",V21,O21)) | X21: =IF($A21="","",INDEX(Assumptions!$D$23:$D$40,T21)) | Y21: =IF($A21="","",IF(P21="",INDEX(Assumptions!$C$45:$C$51,MATCH(D21,Assumptions!$B$45:$B$51,0)),P21)) | Z21: =IF($A21="","",ECL_Calc!AA21)
Q22: =IF($A22="","",F22+G22) | R22: =IF($A22="","",MAX(0,(I22-Assumptions!$C$3)/Assumptions!$C$11)) | S22: =IF($A22="","",MATCH(J22,Assumptions!$B$23:$B$40,0)) | T22: =IF($A22="","",MATCH(K22,Assumptions!$B$23:$B$40,0)) | U22: =IF($A22="","",T22-S22) | V22: =IF($A22="","",IF(OR(L22>Assumptions!$C$7,K22="D",N22="Y"),3,IF(OR(L22>Assumptions!$C$6,M22="Y",AND(U22>=Assumptions!$C$5,NOT(AND(Assumptions!$C$8="Y",T22<=MATCH(Assumptions!$C$9,Assumptions!$B$23:$B$40,0))))),2,1))) | W22: =IF($A22="","",IF(O22="",V22,O22)) | X22: =IF($A22="","",INDEX(Assumptions!$D$23:$D$40,T22)) | Y22: =IF($A22="","",IF(P22="",INDEX(Assumptions!$C$45:$C$51,MATCH(D22,Assumptions!$B$45:$B$51,0)),P22)) | Z22: =IF($A22="","",ECL_Calc!AA22)
Q23: =IF($A23="","",F23+G23) | R23: =IF($A23="","",MAX(0,(I23-Assumptions!$C$3)/Assumptions!$C$11)) | S23: =IF($A23="","",MATCH(J23,Assumptions!$B$23:$B$40,0)) | T23: =IF($A23="","",MATCH(K23,Assumptions!$B$23:$B$40,0)) | U23: =IF($A23="","",T23-S23) | V23: =IF($A23="","",IF(OR(L23>Assumptions!$C$7,K23="D",N23="Y"),3,IF(OR(L23>Assumptions!$C$6,M23="Y",AND(U23>=Assumptions!$C$5,NOT(AND(Assumptions!$C$8="Y",T23<=MATCH(Assumptions!$C$9,Assumptions!$B$23:$B$40,0))))),2,1))) | W23: =IF($A23="","",IF(O23="",V23,O23)) | X23: =IF($A23="","",INDEX(Assumptions!$D$23:$D$40,T23)) | Y23: =IF($A23="","",IF(P23="",INDEX(Assumptions!$C$45:$C$51,MATCH(D23,Assumptions!$B$45:$B$51,0)),P23)) | Z23: =IF($A23="","",ECL_Calc!AA23)
Q24: =IF($A24="","",F24+G24) | R24: =IF($A24="","",MAX(0,(I24-Assumptions!$C$3)/Assumptions!$C$11)) | S24: =IF($A24="","",MATCH(J24,Assumptions!$B$23:$B$40,0)) | T24: =IF($A24="","",MATCH(K24,Assumptions!$B$23:$B$40,0)) | U24: =IF($A24="","",T24-S24) | V24: =IF($A24="","",IF(OR(L24>Assumptions!$C$7,K24="D",N24="Y"),3,IF(OR(L24>Assumptions!$C$6,M24="Y",AND(U24>=Assumptions!$C$5,NOT(AND(Assumptions!$C$8="Y",T24<=MATCH(Assumptions!$C$9,Assumptions!$B$23:$B$40,0))))),2,1))) | W24: =IF($A24="","",IF(O24="",V24,O24)) | X24: =IF($A24="","",INDEX(Assumptions!$D$23:$D$40,T24)) | Y24: =IF($A24="","",IF(P24="",INDEX(Assumptions!$C$45:$C$51,MATCH(D24,Assumptions!$B$45:$B$51,0)),P24)) | Z24: =IF($A24="","",ECL_Calc!AA24)
Q25: =IF($A25="","",F25+G25) | R25: =IF($A25="","",MAX(0,(I25-Assumptions!$C$3)/Assumptions!$C$11)) | S25: =IF($A25="","",MATCH(J25,Assumptions!$B$23:$B$40,0)) | T25: =IF($A25="","",MATCH(K25,Assumptions!$B$23:$B$40,0)) | U25: =IF($A25="","",T25-S25) | V25: =IF($A25="","",IF(OR(L25>Assumptions!$C$7,K25="D",N25="Y"),3,IF(OR(L25>Assumptions!$C$6,M25="Y",AND(U25>=Assumptions!$C$5,NOT(AND(Assumptions!$C$8="Y",T25<=MATCH(Assumptions!$C$9,Assumptions!$B$23:$B$40,0))))),2,1))) | W25: =IF($A25="","",IF(O25="",V25,O25)) | X25: =IF($A25="","",INDEX(Assumptions!$D$23:$D$40,T25)) | Y25: =IF($A25="","",IF(P25="",INDEX(Assumptions!$C$45:$C$51,MATCH(D25,Assumptions!$B$45:$B$51,0)),P25)) | Z25: =IF($A25="","",ECL_Calc!AA25)
... Q55: =IF($A55="","",F55+G55) | R55: =IF($A55="","",MAX(0,(I55-Assumptions!$C$3)/Assumptions!$C$11)) | S55: =IF($A55="","",MATCH(J55,Assumptions!$B$23:$B$40,0)) | T55: =IF($A55="","",MATCH(K55,Assumptions!$B$23:$B$40,0)) | U55: =IF($A55="","",T55-S55) | V55: =IF($A55="","",IF(OR(L55>Assumptions!$C$7,K55="D",N55="Y"),3,IF(OR(L55>Assumptions!$C$6,M55="Y",AND(U55>=Assumptions!$C$5,NOT(AND(Assumptions!$C$8="Y",T55<=MATCH(Assumptions!$C$9,Assumptions!$B$23:$B$40,0))))),2,1))) | W55: =IF($A55="","",IF(O55="",V55,O55)) | X55: =IF($A55="","",INDEX(Assumptions!$D$23:$D$40,T55)) | Y55: =IF($A55="","",IF(P55="",INDEX(Assumptions!$C$45:$C$51,MATCH(D55,Assumptions!$B$45:$B$51,0)),P55)) | Z55: =IF($A55="","",ECL_Calc!AA55)
A57: Total | F57: =SUM(F6:F55) -> 41000000 | G57: =SUM(G6:G55) -> 504500 | Q57: =SUM(Q6:Q55) -> 41504500 | Z57: =SUM(Z6:Z55) -> 1169777

Sheet ECL_Calc
A1: ECL Calculation Engine (no inputs)
A2: Lifetime ECL (closed form, constant hazard): EAD×LGD×[ PD/(1+r) × (1−q^n)/(1−q) + (1−PD)^n × (1−(1−PD)^f)/(1+r)^T ], q=(1−PD)/(1+r), n=INT(T), f=T−n. 12m ECL uses horizon h=MIN(1,T). Reconciled year-by-year in Check_Schedule.
J4: =Assumptions!B15&" scenario (weight "&TEXT(Assumptions!C15,"0%")&")" -> Base scenario (weight 50%) | O4: =Assumptions!B16&" scenario (weight "&TEXT(Assumptions!C16,"0%")&")" -> Upside scenario (weight 20%) | T4: =Assumptions!B17&" scenario (weight "&TEXT(Assumptions!C17,"0%")&")" -> Downside scenario (weight 30%) | Y4: Probability-weighted
A5: Sukuk ID | B5: Final stage | C5: EAD | D5: Term T (yrs) | E5: EIR | F5: 12m PD (TTC) | G5: LGD (base) | H5: n = full yrs | I5: f = part yr | J5: PD | K5: LGD | L5: 12m ECL | M5: Lifetime ECL | N5: Stage ECL | O5: PD | P5: LGD | Q5: 12m ECL | R5: Lifetime ECL | S5: Stage ECL | T5: PD | U5: LGD | V5: 12m ECL | W5: Lifetime ECL | X5: Stage ECL | Y5: 12m ECL | Z5: Lifetime ECL | AA5: Final ECL | AB5: Coverage
A6: =IF(Portfolio!A6="","",Portfolio!A6) -> SK-001 | B6: =IF($A6="","",Portfolio!W6) -> 1 | C6: =IF($A6="","",Portfolio!Q6) -> 10125000 | D6: =IF($A6="","",Portfolio!R6) -> 4.7063655 | E6: =IF($A6="","",Portfolio!H6) -> 0.0475 | F6: =IF($A6="","",Portfolio!X6) -> 0.0004 | G6: =IF($A6="","",Portfolio!Y6) -> 0.4 | H6: =IF($A6="","",INT(D6)) -> 4 | I6: =IF($A6="","",D6-H6) -> 0.7063655 | J6: =IF($A6="","",MIN(Assumptions!$C$10,$F6*Assumptions!$D$15)) -> 0.0004 | K6: =IF($A6="","",MIN(1,$G6*Assumptions!$E$15)) -> 0.4 | L6: =IF($A6="","",$C6*K6*(1-(1-J6)^MIN(1,$D6))/(1+$E6)^MIN(1,$D6)) -> 1546.5394 | M6: =IF($A6="","",$C6*K6*(IF(OR($H6=0,J6=0),0,J6/(1+$E6)*(1-((1-J6)/(1+$E6))^$H6)/(1-(1-J6)/(1+$E6)))+(1-J6)^$H6*(1-(1-J6)^$I6)/(1+$E6)^$D6)) -> 6693.0057 | N6: =IF($A6="","",IF($B6=3,$C6*K6,IF($B6=2,M6,L6))) -> 1546.5394 | O6: =IF($A6="","",MIN(Assumptions!$C$10,$F6*Assumptions!$D$16)) -> 0.00032 | P6: =IF($A6="","",MIN(1,$G6*Assumptions!$E$16)) -> 0.38 | Q6: =IF($A6="","",$C6*P6*(1-(1-O6)^MIN(1,$D6))/(1+$E6)^MIN(1,$D6)) -> 1175.3699 | R6: =IF($A6="","",$C6*P6*(IF(OR($H6=0,O6=0),0,O6/(1+$E6)*(1-((1-O6)/(1+$E6))^$H6)/(1-(1-O6)/(1+$E6)))+(1-O6)^$H6*(1-(1-O6)^$I6)/(1+$E6)^$D6)) -> 5087.4059 | S6: =IF($A6="","",IF($B6=3,$C6*P6,IF($B6=2,R6,Q6))) -> 1175.3699 | T6: =IF($A6="","",MIN(Assumptions!$C$10,$F6*Assumptions!$D$17)) -> 0.00064 | U6: =IF($A6="","",MIN(1,$G6*Assumptions!$E$17)) -> 0.46 | V6: =IF($A6="","",$C6*U6*(1-(1-T6)^MIN(1,$D6))/(1+$E6)^MIN(1,$D6)) -> 2845.6325 | W6: =IF($A6="","",$C6*U6*(IF(OR($H6=0,T6=0),0,T6/(1+$E6)*(1-((1-T6)/(1+$E6))^$H6)/(1-(1-T6)/(1+$E6)))+(1-T6)^$H6*(1-(1-T6)^$I6)/(1+$E6)^$D6)) -> 12309.891 | X6: =IF($A6="","",IF($B6=3,$C6*U6,IF($B6=2,W6,V6))) -> 2845.6325 | Y6: =IF($A6="","",L6*Assumptions!$C$15+Q6*Assumptions!$C$16+V6*Assumptions!$C$17) -> 1862.0334 | Z6: =IF($A6="","",M6*Assumptions!$C$15+R6*Assumptions!$C$16+W6*Assumptions!$C$17) -> 8056.9512 | AA6: =IF($A6="","",N6*Assumptions!$C$15+S6*Assumptions!$C$16+X6*Assumptions!$C$17) -> 1862.0334 | AB6: =IF($A6="","",IF(C6=0,0,AA6/C6)) -> 0.00018390453
A7: =IF(Portfolio!A7="","",Portfolio!A7) -> SK-002 | B7: =IF($A7="","",Portfolio!W7) -> 1 | C7: =IF($A7="","",Portfolio!Q7) -> 5042000 | D7: =IF($A7="","",Portfolio!R7) -> 2.4175222 | E7: =IF($A7="","",Portfolio!H7) -> 0.052 | F7: =IF($A7="","",Portfolio!X7) -> 0.0015 | G7: =IF($A7="","",Portfolio!Y7) -> 0.45 | H7: =IF($A7="","",INT(D7)) -> 2 | I7: =IF($A7="","",D7-H7) -> 0.41752225 | J7: =IF($A7="","",MIN(Assumptions!$C$10,$F7*Assumptions!$D$15)) -> 0.0015 | K7: =IF($A7="","",MIN(1,$G7*Assumptions!$E$15)) -> 0.45 | L7: =IF($A7="","",$C7*K7*(1-(1-J7)^MIN(1,$D7))/(1+$E7)^MIN(1,$D7)) -> 3235.1236 | M7: =IF($A7="","",$C7*K7*(IF(OR($H7=0,J7=0),0,J7/(1+$E7)*(1-((1-J7)/(1+$E7))^$H7)/(1-(1-J7)/(1+$E7)))+(1-J7)^$H7*(1-(1-J7)^$I7)/(1+$E7)^$D7)) -> 7559.5822 | N7: =IF($A7="","",IF($B7=3,$C7*K7,IF($B7=2,M7,L7))) -> 3235.1236 | O7: =IF($A7="","",MIN(Assumptions!$C$10,$F7*Assumptions!$D$16)) -> 0.0012 | P7: =IF($A7="","",MIN(1,$G7*Assumptions!$E$16)) -> 0.4275 | Q7: =IF($A7="","",$C7*P7*(1-(1-O7)^MIN(1,$D7))/(1+$E7)^MIN(1,$D7)) -> 2458.6939 | R7: =IF($A7="","",$C7*P7*(IF(OR($H7=0,O7=0),0,O7/(1+$E7)*(1-((1-O7)/(1+$E7))^$H7)/(1-(1-O7)/(1+$E7)))+(1-O7)^$H7*(1-(1-O7)^$I7)/(1+$E7)^$D7)) -> 5746.4729 | S7: =IF($A7="","",IF($B7=3,$C7*P7,IF($B7=2,R7,Q7))) -> 2458.6939 | T7: =IF($A7="","",MIN(Assumptions!$C$10,$F7*Assumptions!$D$17)) -> 0.0024 | U7: =IF($A7="","",MIN(1,$G7*Assumptions!$E$17)) -> 0.5175 | V7: =IF($A7="","",$C7*U7*(1-(1-T7)^MIN(1,$D7))/(1+$E7)^MIN(1,$D7)) -> 5952.6274 | W7: =IF($A7="","",$C7*U7*(IF(OR($H7=0,T7=0),0,T7/(1+$E7)*(1-((1-T7)/(1+$E7))^$H7)/(1-(1-T7)/(1+$E7)))+(1-T7)^$H7*(1-(1-T7)^$I7)/(1+$E7)^$D7)) -> 13900.986 | X7: =IF($A7="","",IF($B7=3,$C7*U7,IF($B7=2,W7,V7))) -> 5952.6274 | Y7: =IF($A7="","",L7*Assumptions!$C$15+Q7*Assumptions!$C$16+V7*Assumptions!$C$17) -> 3895.0888 | Z7: =IF($A7="","",M7*Assumptions!$C$15+R7*Assumptions!$C$16+W7*Assumptions!$C$17) -> 9099.3815 | AA7: =IF($A7="","",N7*Assumptions!$C$15+S7*Assumptions!$C$16+X7*Assumptions!$C$17) -> 3895.0888 | AB7: =IF($A7="","",IF(C7=0,0,AA7/C7)) -> 0.00077252852
A8: =IF(Portfolio!A8="","",Portfolio!A8) -> SK-003 | B8: =IF($A8="","",Portfolio!W8) -> 2 | C8: =IF($A8="","",Portfolio!Q8) -> 7590000 | D8: =IF($A8="","",Portfolio!R8) -> 4.1396304 | E8: =IF($A8="","",Portfolio!H8) -> 0.061 | F8: =IF($A8="","",Portfolio!X8) -> 0.0055 | G8: =IF($A8="","",Portfolio!Y8) -> 0.35 | H8: =IF($A8="","",INT(D8)) -> 4 | I8: =IF($A8="","",D8-H8) -> 0.13963039 | J8: =IF($A8="","",MIN(Assumptions!$C$10,$F8*Assumptions!$D$15)) -> 0.0055 | K8: =IF($A8="","",MIN(1,$G8*Assumptions!$E$15)) -> 0.35 | L8: =IF($A8="","",$C8*K8*(1-(1-J8)^MIN(1,$D8))/(1+$E8)^MIN(1,$D8)) -> 13770.735 | M8: =IF($A8="","",$C8*K8*(IF(OR($H8=0,J8=0),0,J8/(1+$E8)*(1-((1-J8)/(1+$E8))^$H8)/(1-(1-J8)/(1+$E8)))+(1-J8)^$H8*(1-(1-J8)^$I8)/(1+$E8)^$D8)) -> 51682.795 | N8: =IF($A8="","",IF($B8=3,$C8*K8,IF($B8=2,M8,L8))) -> 51682.795 | O8: =IF($A8="","",MIN(Assumptions!$C$10,$F8*Assumptions!$D$16)) -> 0.0044 | P8: =IF($A8="","",MIN(1,$G8*Assumptions!$E$16)) -> 0.3325 | Q8: =IF($A8="","",$C8*P8*(1-(1-O8)^MIN(1,$D8))/(1+$E8)^MIN(1,$D8)) -> 10465.759 | R8: =IF($A8="","",$C8*P8*(IF(OR($H8=0,O8=0),0,O8/(1+$E8)*(1-((1-O8)/(1+$E8))^$H8)/(1-(1-O8)/(1+$E8)))+(1-O8)^$H8*(1-(1-O8)^$I8)/(1+$E8)^$D8)) -> 39343.463 | S8: =IF($A8="","",IF($B8=3,$C8*P8,IF($B8=2,R8,Q8))) -> 39343.463 | T8: =IF($A8="","",MIN(Assumptions!$C$10,$F8*Assumptions!$D$17)) -> 0.0088 | U8: =IF($A8="","",MIN(1,$G8*Assumptions!$E$17)) -> 0.4025 | V8: =IF($A8="","",$C8*U8*(1-(1-T8)^MIN(1,$D8))/(1+$E8)^MIN(1,$D8)) -> 25338.153 | W8: =IF($A8="","",$C8*U8*(IF(OR($H8=0,T8=0),0,T8/(1+$E8)*(1-((1-T8)/(1+$E8))^$H8)/(1-(1-T8)/(1+$E8)))+(1-T8)^$H8*(1-(1-T8)^$I8)/(1+$E8)^$D8)) -> 94629.031 | X8: =IF($A8="","",IF($B8=3,$C8*U8,IF($B8=2,W8,V8))) -> 94629.031 | Y8: =IF($A8="","",L8*Assumptions!$C$15+Q8*Assumptions!$C$16+V8*Assumptions!$C$17) -> 16579.965 | Z8: =IF($A8="","",M8*Assumptions!$C$15+R8*Assumptions!$C$16+W8*Assumptions!$C$17) -> 62098.8 | AA8: =IF($A8="","",N8*Assumptions!$C$15+S8*Assumptions!$C$16+X8*Assumptions!$C$17) -> 62098.8 | AB8: =IF($A8="","",IF(C8=0,0,AA8/C8)) -> 0.00818166
A9: =IF(Portfolio!A9="","",Portfolio!A9) -> SK-004 | B9: =IF($A9="","",Portfolio!W9) -> 1 | C9: =IF($A9="","",Portfolio!Q9) -> 3015500 | D9: =IF($A9="","",Portfolio!R9) -> 0.58042437 | E9: =IF($A9="","",Portfolio!H9) -> 0.056 | F9: =IF($A9="","",Portfolio!X9) -> 0.001 | G9: =IF($A9="","",Portfolio!Y9) -> 0.45 | H9: =IF($A9="","",INT(D9)) -> 0 | I9: =IF($A9="","",D9-H9) -> 0.58042437 | J9: =IF($A9="","",MIN(Assumptions!$C$10,$F9*Assumptions!$D$15)) -> 0.001 | K9: =IF($A9="","",MIN(1,$G9*Assumptions!$E$15)) -> 0.45 | L9: =IF($A9="","",$C9*K9*(1-(1-J9)^MIN(1,$D9))/(1+$E9)^MIN(1,$D9)) -> 763.26177 | M9: =IF($A9="","",$C9*K9*(IF(OR($H9=0,J9=0),0,J9/(1+$E9)*(1-((1-J9)/(1+$E9))^$H9)/(1-(1-J9)/(1+$E9)))+(1-J9)^$H9*(1-(1-J9)^$I9)/(1+$E9)^$D9)) -> 763.26177 | N9: =IF($A9="","",IF($B9=3,$C9*K9,IF($B9=2,M9,L9))) -> 763.26177 | O9: =IF($A9="","",MIN(Assumptions!$C$10,$F9*Assumptions!$D$16)) -> 0.0008 | P9: =IF($A9="","",MIN(1,$G9*Assumptions!$E$16)) -> 0.4275 | Q9: =IF($A9="","",$C9*P9*(1-(1-O9)^MIN(1,$D9))/(1+$E9)^MIN(1,$D9)) -> 580.05459 | R9: =IF($A9="","",$C9*P9*(IF(OR($H9=0,O9=0),0,O9/(1+$E9)*(1-((1-O9)/(1+$E9))^$H9)/(1-(1-O9)/(1+$E9)))+(1-O9)^$H9*(1-(1-O9)^$I9)/(1+$E9)^$D9)) -> 580.05459 | S9: =IF($A9="","",IF($B9=3,$C9*P9,IF($B9=2,R9,Q9))) -> 580.05459 | T9: =IF($A9="","",MIN(Assumptions!$C$10,$F9*Assumptions!$D$17)) -> 0.0016 | U9: =IF($A9="","",MIN(1,$G9*Assumptions!$E$17)) -> 0.5175 | V9: =IF($A9="","",$C9*U9*(1-(1-T9)^MIN(1,$D9))/(1+$E9)^MIN(1,$D9)) -> 1404.5786 | W9: =IF($A9="","",$C9*U9*(IF(OR($H9=0,T9=0),0,T9/(1+$E9)*(1-((1-T9)/(1+$E9))^$H9)/(1-(1-T9)/(1+$E9)))+(1-T9)^$H9*(1-(1-T9)^$I9)/(1+$E9)^$D9)) -> 1404.5786 | X9: =IF($A9="","",IF($B9=3,$C9*U9,IF($B9=2,W9,V9))) -> 1404.5786 | Y9: =IF($A9="","",L9*Assumptions!$C$15+Q9*Assumptions!$C$16+V9*Assumptions!$C$17) -> 919.01539 | Z9: =IF($A9="","",M9*Assumptions!$C$15+R9*Assumptions!$C$16+W9*Assumptions!$C$17) -> 919.01539 | AA9: =IF($A9="","",N9*Assumptions!$C$15+S9*Assumptions!$C$16+X9*Assumptions!$C$17) -> 919.01539 | AB9: =IF($A9="","",IF(C9=0,0,AA9/C9)) -> 0.00030476385
A10: =IF(Portfolio!A10="","",Portfolio!A10) -> SK-005 | B10: =IF($A10="","",Portfolio!W10) -> 2 | C10: =IF($A10="","",Portfolio!Q10) -> 4038000 | D10: =IF($A10="","",Portfolio!R10) -> 6.9459274 | E10: =IF($A10="","",Portfolio!H10) -> 0.059 | F10: =IF($A10="","",Portfolio!X10) -> 0.0025 | G10: =IF($A10="","",Portfolio!Y10) -> 0.45 | H10: =IF($A10="","",INT(D10)) -> 6 | I10: =IF($A10="","",D10-H10) -> 0.94592745 | J10: =IF($A10="","",MIN(Assumptions!$C$10,$F10*Assumptions!$D$15)) -> 0.0025 | K10: =IF($A10="","",MIN(1,$G10*Assumptions!$E$15)) -> 0.45 | L10: =IF($A10="","",$C10*K10*(1-(1-J10)^MIN(1,$D10))/(1+$E10)^MIN(1,$D10)) -> 4289.6601 | M10: =IF($A10="","",$C10*K10*(IF(OR($H10=0,J10=0),0,J10/(1+$E10)*(1-((1-J10)/(1+$E10))^$H10)/(1-(1-J10)/(1+$E10)))+(1-J10)^$H10*(1-(1-J10)^$I10)/(1+$E10)^$D10)) -> 25121.122 | N10: =IF($A10="","",IF($B10=3,$C10*K10,IF($B10=2,M10,L10))) -> 25121.122 | O10: =IF($A10="","",MIN(Assumptions!$C$10,$F10*Assumptions!$D$16)) -> 0.002 | P10: =IF($A10="","",MIN(1,$G10*Assumptions!$E$16)) -> 0.4275 | Q10: =IF($A10="","",$C10*P10*(1-(1-O10)^MIN(1,$D10))/(1+$E10)^MIN(1,$D10)) -> 3260.1416 | R10: =IF($A10="","",$C10*P10*(IF(OR($H10=0,O10=0),0,O10/(1+$E10)*(1-((1-O10)/(1+$E10))^$H10)/(1-(1-O10)/(1+$E10)))+(1-O10)^$H10*(1-(1-O10)^$I10)/(1+$E10)^$D10)) -> 19118.282 | S10: =IF($A10="","",IF($B10=3,$C10*P10,IF($B10=2,R10,Q10))) -> 19118.282 | T10: =IF($A10="","",MIN(Assumptions!$C$10,$F10*Assumptions!$D$17)) -> 0.004 | U10: =IF($A10="","",MIN(1,$G10*Assumptions!$E$17)) -> 0.5175 | V10: =IF($A10="","",$C10*U10*(1-(1-T10)^MIN(1,$D10))/(1+$E10)^MIN(1,$D10)) -> 7892.9745 | W10: =IF($A10="","",$C10*U10*(IF(OR($H10=0,T10=0),0,T10/(1+$E10)*(1-((1-T10)/(1+$E10))^$H10)/(1-(1-T10)/(1+$E10)))+(1-T10)^$H10*(1-(1-T10)^$I10)/(1+$E10)^$D10)) -> 46032.961 | X10: =IF($A10="","",IF($B10=3,$C10*U10,IF($B10=2,W10,V10))) -> 46032.961 | Y10: =IF($A10="","",L10*Assumptions!$C$15+Q10*Assumptions!$C$16+V10*Assumptions!$C$17) -> 5164.7507 | Z10: =IF($A10="","",M10*Assumptions!$C$15+R10*Assumptions!$C$16+W10*Assumptions!$C$17) -> 30194.106 | AA10: =IF($A10="","",N10*Assumptions!$C$15+S10*Assumptions!$C$16+X10*Assumptions!$C$17) -> 30194.106 | AB10: =IF($A10="","",IF(C10=0,0,AA10/C10)) -> 0.0074774903
A11: =IF(Portfolio!A11="","",Portfolio!A11) -> SK-006 | B11: =IF($A11="","",Portfolio!W11) -> 2 | C11: =IF($A11="","",Portfolio!Q11) -> 2060000 | D11: =IF($A11="","",Portfolio!R11) -> 1.412731 | E11: =IF($A11="","",Portfolio!H11) -> 0.085 | F11: =IF($A11="","",Portfolio!X11) -> 0.05 | G11: =IF($A11="","",Portfolio!Y11) -> 0.6 | H11: =IF($A11="","",INT(D11)) -> 1 | I11: =IF($A11="","",D11-H11) -> 0.41273101 | J11: =IF($A11="","",MIN(Assumptions!$C$10,$F11*Assumptions!$D$15)) -> 0.05 | K11: =IF($A11="","",MIN(1,$G11*Assumptions!$E$15)) -> 0.6 | L11: =IF($A11="","",$C11*K11*(1-(1-J11)^MIN(1,$D11))/(1+$E11)^MIN(1,$D11)) -> 56958.525 | M11: =IF($A11="","",$C11*K11*(IF(OR($H11=0,J11=0),0,J11/(1+$E11)*(1-((1-J11)/(1+$E11))^$H11)/(1-(1-J11)/(1+$E11)))+(1-J11)^$H11*(1-(1-J11)^$I11)/(1+$E11)^$D11)) -> 78877.897 | N11: =IF($A11="","",IF($B11=3,$C11*K11,IF($B11=2,M11,L11))) -> 78877.897 | O11: =IF($A11="","",MIN(Assumptions!$C$10,$F11*Assumptions!$D$16)) -> 0.04 | P11: =IF($A11="","",MIN(1,$G11*Assumptions!$E$16)) -> 0.57 | Q11: =IF($A11="","",$C11*P11*(1-(1-O11)^MIN(1,$D11))/(1+$E11)^MIN(1,$D11)) -> 43288.479 | R11: =IF($A11="","",$C11*P11*(IF(OR($H11=0,O11=0),0,O11/(1+$E11)*(1-((1-O11)/(1+$E11))^$H11)/(1-(1-O11)/(1+$E11)))+(1-O11)^$H11*(1-(1-O11)^$I11)/(1+$E11)^$D11)) -> 60071.436 | S11: =IF($A11="","",IF($B11=3,$C11*P11,IF($B11=2,R11,Q11))) -> 60071.436 | T11: =IF($A11="","",MIN(Assumptions!$C$10,$F11*Assumptions!$D$17)) -> 0.08 | U11: =IF($A11="","",MIN(1,$G11*Assumptions!$E$17)) -> 0.69 | V11: =IF($A11="","",$C11*U11*(1-(1-T11)^MIN(1,$D11))/(1+$E11)^MIN(1,$D11)) -> 104803.69 | W11: =IF($A11="","",$C11*U11*(IF(OR($H11=0,T11=0),0,T11/(1+$E11)*(1-((1-T11)/(1+$E11))^$H11)/(1-(1-T11)/(1+$E11)))+(1-T11)^$H11*(1-(1-T11)^$I11)/(1+$E11)^$D11)) -> 144225.56 | X11: =IF($A11="","",IF($B11=3,$C11*U11,IF($B11=2,W11,V11))) -> 144225.56 | Y11: =IF($A11="","",L11*Assumptions!$C$15+Q11*Assumptions!$C$16+V11*Assumptions!$C$17) -> 68578.065 | Z11: =IF($A11="","",M11*Assumptions!$C$15+R11*Assumptions!$C$16+W11*Assumptions!$C$17) -> 94720.905 | AA11: =IF($A11="","",N11*Assumptions!$C$15+S11*Assumptions!$C$16+X11*Assumptions!$C$17) -> 94720.905 | AB11: =IF($A11="","",IF(C11=0,0,AA11/C11)) -> 0.045981022
A12: =IF(Portfolio!A12="","",Portfolio!A12) -> SK-007 | B12: =IF($A12="","",Portfolio!W12) -> 3 | C12: =IF($A12="","",Portfolio!Q12) -> 1570000 | D12: =IF($A12="","",Portfolio!R12) -> 1.2511978 | E12: =IF($A12="","",Portfolio!H12) -> 0.09 | F12: =IF($A12="","",Portfolio!X12) -> 1 | G12: =IF($A12="","",Portfolio!Y12) -> 0.6 | H12: =IF($A12="","",INT(D12)) -> 1 | I12: =IF($A12="","",D12-H12) -> 0.25119781 | J12: =IF($A12="","",MIN(Assumptions!$C$10,$F12*Assumptions!$D$15)) -> 0.9999 | K12: =IF($A12="","",MIN(1,$G12*Assumptions!$E$15)) -> 0.6 | L12: =IF($A12="","",$C12*K12*(1-(1-J12)^MIN(1,$D12))/(1+$E12)^MIN(1,$D12)) -> 864133.76 | M12: =IF($A12="","",$C12*K12*(IF(OR($H12=0,J12=0),0,J12/(1+$E12)*(1-((1-J12)/(1+$E12))^$H12)/(1-(1-J12)/(1+$E12)))+(1-J12)^$H12*(1-(1-J12)^$I12)/(1+$E12)^$D12)) -> 864209.97 | N12: =IF($A12="","",IF($B12=3,$C12*K12,IF($B12=2,M12,L12))) -> 942000 | O12: =IF($A12="","",MIN(Assumptions!$C$10,$F12*Assumptions!$D$16)) -> 0.8 | P12: =IF($A12="","",MIN(1,$G12*Assumptions!$E$16)) -> 0.57 | Q12: =IF($A12="","",$C12*P12*(1-(1-O12)^MIN(1,$D12))/(1+$E12)^MIN(1,$D12)) -> 656807.34 | R12: =IF($A12="","",$C12*P12*(IF(OR($H12=0,O12=0),0,O12/(1+$E12)*(1-((1-O12)/(1+$E12))^$H12)/(1-(1-O12)/(1+$E12)))+(1-O12)^$H12*(1-(1-O12)^$I12)/(1+$E12)^$D12)) -> 710242.91 | S12: =IF($A12="","",IF($B12=3,$C12*P12,IF($B12=2,R12,Q12))) -> 894900 | T12: =IF($A12="","",MIN(Assumptions!$C$10,$F12*Assumptions!$D$17)) -> 0.9999 | U12: =IF($A12="","",MIN(1,$G12*Assumptions!$E$17)) -> 0.69 | V12: =IF($A12="","",$C12*U12*(1-(1-T12)^MIN(1,$D12))/(1+$E12)^MIN(1,$D12)) -> 993753.83 | W12: =IF($A12="","",$C12*U12*(IF(OR($H12=0,T12=0),0,T12/(1+$E12)*(1-((1-T12)/(1+$E12))^$H12)/(1-(1-T12)/(1+$E12)))+(1-T12)^$H12*(1-(1-T12)^$I12)/(1+$E12)^$D12)) -> 993841.46 | X12: =IF($A12="","",IF($B12=3,$C12*U12,IF($B12=2,W12,V12))) -> 1083300 | Y12: =IF($A12="","",L12*Assumptions!$C$15+Q12*Assumptions!$C$16+V12*Assumptions!$C$17) -> 861554.5 | Z12: =IF($A12="","",M12*Assumptions!$C$15+R12*Assumptions!$C$16+W12*Assumptions!$C$17) -> 872306 | AA12: =IF($A12="","",N12*Assumptions!$C$15+S12*Assumptions!$C$16+X12*Assumptions!$C$17) -> 974970 | AB12: =IF($A12="","",IF(C12=0,0,AA12/C12)) -> 0.621
A13: =IF(Portfolio!A13="","",Portfolio!A13) -> SK-008 | B13: =IF($A13="","",Portfolio!W13) -> 1 | C13: =IF($A13="","",Portfolio!Q13) -> 8064000 | D13: =IF($A13="","",Portfolio!R13) -> 9.2922656 | E13: =IF($A13="","",Portfolio!H13) -> 0.043 | F13: =IF($A13="","",Portfolio!X13) -> 0.0003 | G13: =IF($A13="","",Portfolio!Y13) -> 0.4 | H13: =IF($A13="","",INT(D13)) -> 9 | I13: =IF($A13="","",D13-H13) -> 0.29226557 | J13: =IF($A13="","",MIN(Assumptions!$C$10,$F13*Assumptions!$D$15)) -> 0.0003 | K13: =IF($A13="","",MIN(1,$G13*Assumptions!$E$15)) -> 0.4 | L13: =IF($A13="","",$C13*K13*(1-(1-J13)^MIN(1,$D13))/(1+$E13)^MIN(1,$D13)) -> 927.78523 | M13: =IF($A13="","",$C13*K13*(IF(OR($H13=0,J13=0),0,J13/(1+$E13)*(1-((1-J13)/(1+$E13))^$H13)/(1-(1-J13)/(1+$E13)))+(1-J13)^$H13*(1-(1-J13)^$I13)/(1+$E13)^$D13)) -> 7280.5079 | N13: =IF($A13="","",IF($B13=3,$C13*K13,IF($B13=2,M13,L13))) -> 927.78523 | O13: =IF($A13="","",MIN(Assumptions!$C$10,$F13*Assumptions!$D$16)) -> 0.00024 | P13: =IF($A13="","",MIN(1,$G13*Assumptions!$E$16)) -> 0.38 | Q13: =IF($A13="","",$C13*P13*(1-(1-O13)^MIN(1,$D13))/(1+$E13)^MIN(1,$D13)) -> 705.11678 | R13: =IF($A13="","",$C13*P13*(IF(OR($H13=0,O13=0),0,O13/(1+$E13)*(1-((1-O13)/(1+$E13))^$H13)/(1-(1-O13)/(1+$E13)))+(1-O13)^$H13*(1-(1-O13)^$I13)/(1+$E13)^$D13)) -> 5534.4638 | S13: =IF($A13="","",IF($B13=3,$C13*P13,IF($B13=2,R13,Q13))) -> 705.11678 | T13: =IF($A13="","",MIN(Assumptions!$C$10,$F13*Assumptions!$D$17)) -> 0.00048 | U13: =IF($A13="","",MIN(1,$G13*Assumptions!$E$17)) -> 0.46 | V13: =IF($A13="","",$C13*U13*(1-(1-T13)^MIN(1,$D13))/(1+$E13)^MIN(1,$D13)) -> 1707.1248 | W13: =IF($A13="","",$C13*U13*(IF(OR($H13=0,T13=0),0,T13/(1+$E13)*(1-((1-T13)/(1+$E13))^$H13)/(1-(1-T13)/(1+$E13)))+(1-T13)^$H13*(1-(1-T13)^$I13)/(1+$E13)^$D13)) -> 13386.859 | X13: =IF($A13="","",IF($B13=3,$C13*U13,IF($B13=2,W13,V13))) -> 1707.1248 | Y13: =IF($A13="","",L13*Assumptions!$C$15+Q13*Assumptions!$C$16+V13*Assumptions!$C$17) -> 1117.0534 | Z13: =IF($A13="","",M13*Assumptions!$C$15+R13*Assumptions!$C$16+W13*Assumptions!$C$17) -> 8763.2044 | AA13: =IF($A13="","",N13*Assumptions!$C$15+S13*Assumptions!$C$16+X13*Assumptions!$C$17) -> 1117.0534 | AB13: =IF($A13="","",IF(C13=0,0,AA13/C13)) -> 0.00013852349
A14: =IF(Portfolio!A14="","",Portfolio!A14) | B14: =IF($A14="","",Portfolio!W14) | C14: =IF($A14="","",Portfolio!Q14) | D14: =IF($A14="","",Portfolio!R14) | E14: =IF($A14="","",Portfolio!H14) | F14: =IF($A14="","",Portfolio!X14) | G14: =IF($A14="","",Portfolio!Y14) | H14: =IF($A14="","",INT(D14)) | I14: =IF($A14="","",D14-H14) | J14: =IF($A14="","",MIN(Assumptions!$C$10,$F14*Assumptions!$D$15)) | K14: =IF($A14="","",MIN(1,$G14*Assumptions!$E$15)) | L14: =IF($A14="","",$C14*K14*(1-(1-J14)^MIN(1,$D14))/(1+$E14)^MIN(1,$D14)) | M14: =IF($A14="","",$C14*K14*(IF(OR($H14=0,J14=0),0,J14/(1+$E14)*(1-((1-J14)/(1+$E14))^$H14)/(1-(1-J14)/(1+$E14)))+(1-J14)^$H14*(1-(1-J14)^$I14)/(1+$E14)^$D14)) | N14: =IF($A14="","",IF($B14=3,$C14*K14,IF($B14=2,M14,L14))) | O14: =IF($A14="","",MIN(Assumptions!$C$10,$F14*Assumptions!$D$16)) | P14: =IF($A14="","",MIN(1,$G14*Assumptions!$E$16)) | Q14: =IF($A14="","",$C14*P14*(1-(1-O14)^MIN(1,$D14))/(1+$E14)^MIN(1,$D14)) | R14: =IF($A14="","",$C14*P14*(IF(OR($H14=0,O14=0),0,O14/(1+$E14)*(1-((1-O14)/(1+$E14))^$H14)/(1-(1-O14)/(1+$E14)))+(1-O14)^$H14*(1-(1-O14)^$I14)/(1+$E14)^$D14)) | S14: =IF($A14="","",IF($B14=3,$C14*P14,IF($B14=2,R14,Q14))) | T14: =IF($A14="","",MIN(Assumptions!$C$10,$F14*Assumptions!$D$17)) | U14: =IF($A14="","",MIN(1,$G14*Assumptions!$E$17)) | V14: =IF($A14="","",$C14*U14*(1-(1-T14)^MIN(1,$D14))/(1+$E14)^MIN(1,$D14)) | W14: =IF($A14="","",$C14*U14*(IF(OR($H14=0,T14=0),0,T14/(1+$E14)*(1-((1-T14)/(1+$E14))^$H14)/(1-(1-T14)/(1+$E14)))+(1-T14)^$H14*(1-(1-T14)^$I14)/(1+$E14)^$D14)) | X14: =IF($A14="","",IF($B14=3,$C14*U14,IF($B14=2,W14,V14))) | Y14: =IF($A14="","",L14*Assumptions!$C$15+Q14*Assumptions!$C$16+V14*Assumptions!$C$17) | Z14: =IF($A14="","",M14*Assumptions!$C$15+R14*Assumptions!$C$16+W14*Assumptions!$C$17) | AA14: =IF($A14="","",N14*Assumptions!$C$15+S14*Assumptions!$C$16+X14*Assumptions!$C$17) | AB14: =IF($A14="","",IF(C14=0,0,AA14/C14))
A15: =IF(Portfolio!A15="","",Portfolio!A15) | B15: =IF($A15="","",Portfolio!W15) | C15: =IF($A15="","",Portfolio!Q15) | D15: =IF($A15="","",Portfolio!R15) | E15: =IF($A15="","",Portfolio!H15) | F15: =IF($A15="","",Portfolio!X15) | G15: =IF($A15="","",Portfolio!Y15) | H15: =IF($A15="","",INT(D15)) | I15: =IF($A15="","",D15-H15) | J15: =IF($A15="","",MIN(Assumptions!$C$10,$F15*Assumptions!$D$15)) | K15: =IF($A15="","",MIN(1,$G15*Assumptions!$E$15)) | L15: =IF($A15="","",$C15*K15*(1-(1-J15)^MIN(1,$D15))/(1+$E15)^MIN(1,$D15)) | M15: =IF($A15="","",$C15*K15*(IF(OR($H15=0,J15=0),0,J15/(1+$E15)*(1-((1-J15)/(1+$E15))^$H15)/(1-(1-J15)/(1+$E15)))+(1-J15)^$H15*(1-(1-J15)^$I15)/(1+$E15)^$D15)) | N15: =IF($A15="","",IF($B15=3,$C15*K15,IF($B15=2,M15,L15))) | O15: =IF($A15="","",MIN(Assumptions!$C$10,$F15*Assumptions!$D$16)) | P15: =IF($A15="","",MIN(1,$G15*Assumptions!$E$16)) | Q15: =IF($A15="","",$C15*P15*(1-(1-O15)^MIN(1,$D15))/(1+$E15)^MIN(1,$D15)) | R15: =IF($A15="","",$C15*P15*(IF(OR($H15=0,O15=0),0,O15/(1+$E15)*(1-((1-O15)/(1+$E15))^$H15)/(1-(1-O15)/(1+$E15)))+(1-O15)^$H15*(1-(1-O15)^$I15)/(1+$E15)^$D15)) | S15: =IF($A15="","",IF($B15=3,$C15*P15,IF($B15=2,R15,Q15))) | T15: =IF($A15="","",MIN(Assumptions!$C$10,$F15*Assumptions!$D$17)) | U15: =IF($A15="","",MIN(1,$G15*Assumptions!$E$17)) | V15: =IF($A15="","",$C15*U15*(1-(1-T15)^MIN(1,$D15))/(1+$E15)^MIN(1,$D15)) | W15: =IF($A15="","",$C15*U15*(IF(OR($H15=0,T15=0),0,T15/(1+$E15)*(1-((1-T15)/(1+$E15))^$H15)/(1-(1-T15)/(1+$E15)))+(1-T15)^$H15*(1-(1-T15)^$I15)/(1+$E15)^$D15)) | X15: =IF($A15="","",IF($B15=3,$C15*U15,IF($B15=2,W15,V15))) | Y15: =IF($A15="","",L15*Assumptions!$C$15+Q15*Assumptions!$C$16+V15*Assumptions!$C$17) | Z15: =IF($A15="","",M15*Assumptions!$C$15+R15*Assumptions!$C$16+W15*Assumptions!$C$17) | AA15: =IF($A15="","",N15*Assumptions!$C$15+S15*Assumptions!$C$16+X15*Assumptions!$C$17) | AB15: =IF($A15="","",IF(C15=0,0,AA15/C15))
A16: =IF(Portfolio!A16="","",Portfolio!A16) | B16: =IF($A16="","",Portfolio!W16) | C16: =IF($A16="","",Portfolio!Q16) | D16: =IF($A16="","",Portfolio!R16) | E16: =IF($A16="","",Portfolio!H16) | F16: =IF($A16="","",Portfolio!X16) | G16: =IF($A16="","",Portfolio!Y16) | H16: =IF($A16="","",INT(D16)) | I16: =IF($A16="","",D16-H16) | J16: =IF($A16="","",MIN(Assumptions!$C$10,$F16*Assumptions!$D$15)) | K16: =IF($A16="","",MIN(1,$G16*Assumptions!$E$15)) | L16: =IF($A16="","",$C16*K16*(1-(1-J16)^MIN(1,$D16))/(1+$E16)^MIN(1,$D16)) | M16: =IF($A16="","",$C16*K16*(IF(OR($H16=0,J16=0),0,J16/(1+$E16)*(1-((1-J16)/(1+$E16))^$H16)/(1-(1-J16)/(1+$E16)))+(1-J16)^$H16*(1-(1-J16)^$I16)/(1+$E16)^$D16)) | N16: =IF($A16="","",IF($B16=3,$C16*K16,IF($B16=2,M16,L16))) | O16: =IF($A16="","",MIN(Assumptions!$C$10,$F16*Assumptions!$D$16)) | P16: =IF($A16="","",MIN(1,$G16*Assumptions!$E$16)) | Q16: =IF($A16="","",$C16*P16*(1-(1-O16)^MIN(1,$D16))/(1+$E16)^MIN(1,$D16)) | R16: =IF($A16="","",$C16*P16*(IF(OR($H16=0,O16=0),0,O16/(1+$E16)*(1-((1-O16)/(1+$E16))^$H16)/(1-(1-O16)/(1+$E16)))+(1-O16)^$H16*(1-(1-O16)^$I16)/(1+$E16)^$D16)) | S16: =IF($A16="","",IF($B16=3,$C16*P16,IF($B16=2,R16,Q16))) | T16: =IF($A16="","",MIN(Assumptions!$C$10,$F16*Assumptions!$D$17)) | U16: =IF($A16="","",MIN(1,$G16*Assumptions!$E$17)) | V16: =IF($A16="","",$C16*U16*(1-(1-T16)^MIN(1,$D16))/(1+$E16)^MIN(1,$D16)) | W16: =IF($A16="","",$C16*U16*(IF(OR($H16=0,T16=0),0,T16/(1+$E16)*(1-((1-T16)/(1+$E16))^$H16)/(1-(1-T16)/(1+$E16)))+(1-T16)^$H16*(1-(1-T16)^$I16)/(1+$E16)^$D16)) | X16: =IF($A16="","",IF($B16=3,$C16*U16,IF($B16=2,W16,V16))) | Y16: =IF($A16="","",L16*Assumptions!$C$15+Q16*Assumptions!$C$16+V16*Assumptions!$C$17) | Z16: =IF($A16="","",M16*Assumptions!$C$15+R16*Assumptions!$C$16+W16*Assumptions!$C$17) | AA16: =IF($A16="","",N16*Assumptions!$C$15+S16*Assumptions!$C$16+X16*Assumptions!$C$17) | AB16: =IF($A16="","",IF(C16=0,0,AA16/C16))
A17: =IF(Portfolio!A17="","",Portfolio!A17) | B17: =IF($A17="","",Portfolio!W17) | C17: =IF($A17="","",Portfolio!Q17) | D17: =IF($A17="","",Portfolio!R17) | E17: =IF($A17="","",Portfolio!H17) | F17: =IF($A17="","",Portfolio!X17) | G17: =IF($A17="","",Portfolio!Y17) | H17: =IF($A17="","",INT(D17)) | I17: =IF($A17="","",D17-H17) | J17: =IF($A17="","",MIN(Assumptions!$C$10,$F17*Assumptions!$D$15)) | K17: =IF($A17="","",MIN(1,$G17*Assumptions!$E$15)) | L17: =IF($A17="","",$C17*K17*(1-(1-J17)^MIN(1,$D17))/(1+$E17)^MIN(1,$D17)) | M17: =IF($A17="","",$C17*K17*(IF(OR($H17=0,J17=0),0,J17/(1+$E17)*(1-((1-J17)/(1+$E17))^$H17)/(1-(1-J17)/(1+$E17)))+(1-J17)^$H17*(1-(1-J17)^$I17)/(1+$E17)^$D17)) | N17: =IF($A17="","",IF($B17=3,$C17*K17,IF($B17=2,M17,L17))) | O17: =IF($A17="","",MIN(Assumptions!$C$10,$F17*Assumptions!$D$16)) | P17: =IF($A17="","",MIN(1,$G17*Assumptions!$E$16)) | Q17: =IF($A17="","",$C17*P17*(1-(1-O17)^MIN(1,$D17))/(1+$E17)^MIN(1,$D17)) | R17: =IF($A17="","",$C17*P17*(IF(OR($H17=0,O17=0),0,O17/(1+$E17)*(1-((1-O17)/(1+$E17))^$H17)/(1-(1-O17)/(1+$E17)))+(1-O17)^$H17*(1-(1-O17)^$I17)/(1+$E17)^$D17)) | S17: =IF($A17="","",IF($B17=3,$C17*P17,IF($B17=2,R17,Q17))) | T17: =IF($A17="","",MIN(Assumptions!$C$10,$F17*Assumptions!$D$17)) | U17: =IF($A17="","",MIN(1,$G17*Assumptions!$E$17)) | V17: =IF($A17="","",$C17*U17*(1-(1-T17)^MIN(1,$D17))/(1+$E17)^MIN(1,$D17)) | W17: =IF($A17="","",$C17*U17*(IF(OR($H17=0,T17=0),0,T17/(1+$E17)*(1-((1-T17)/(1+$E17))^$H17)/(1-(1-T17)/(1+$E17)))+(1-T17)^$H17*(1-(1-T17)^$I17)/(1+$E17)^$D17)) | X17: =IF($A17="","",IF($B17=3,$C17*U17,IF($B17=2,W17,V17))) | Y17: =IF($A17="","",L17*Assumptions!$C$15+Q17*Assumptions!$C$16+V17*Assumptions!$C$17) | Z17: =IF($A17="","",M17*Assumptions!$C$15+R17*Assumptions!$C$16+W17*Assumptions!$C$17) | AA17: =IF($A17="","",N17*Assumptions!$C$15+S17*Assumptions!$C$16+X17*Assumptions!$C$17) | AB17: =IF($A17="","",IF(C17=0,0,AA17/C17))
... A55: =IF(Portfolio!A55="","",Portfolio!A55) | B55: =IF($A55="","",Portfolio!W55) | C55: =IF($A55="","",Portfolio!Q55) | D55: =IF($A55="","",Portfolio!R55) | E55: =IF($A55="","",Portfolio!H55) | F55: =IF($A55="","",Portfolio!X55) | G55: =IF($A55="","",Portfolio!Y55) | H55: =IF($A55="","",INT(D55)) | I55: =IF($A55="","",D55-H55) | J55: =IF($A55="","",MIN(Assumptions!$C$10,$F55*Assumptions!$D$15)) | K55: =IF($A55="","",MIN(1,$G55*Assumptions!$E$15)) | L55: =IF($A55="","",$C55*K55*(1-(1-J55)^MIN(1,$D55))/(1+$E55)^MIN(1,$D55)) | M55: =IF($A55="","",$C55*K55*(IF(OR($H55=0,J55=0),0,J55/(1+$E55)*(1-((1-J55)/(1+$E55))^$H55)/(1-(1-J55)/(1+$E55)))+(1-J55)^$H55*(1-(1-J55)^$I55)/(1+$E55)^$D55)) | N55: =IF($A55="","",IF($B55=3,$C55*K55,IF($B55=2,M55,L55))) | O55: =IF($A55="","",MIN(Assumptions!$C$10,$F55*Assumptions!$D$16)) | P55: =IF($A55="","",MIN(1,$G55*Assumptions!$E$16)) | Q55: =IF($A55="","",$C55*P55*(1-(1-O55)^MIN(1,$D55))/(1+$E55)^MIN(1,$D55)) | R55: =IF($A55="","",$C55*P55*(IF(OR($H55=0,O55=0),0,O55/(1+$E55)*(1-((1-O55)/(1+$E55))^$H55)/(1-(1-O55)/(1+$E55)))+(1-O55)^$H55*(1-(1-O55)^$I55)/(1+$E55)^$D55)) | S55: =IF($A55="","",IF($B55=3,$C55*P55,IF($B55=2,R55,Q55))) | T55: =IF($A55="","",MIN(Assumptions!$C$10,$F55*Assumptions!$D$17)) | U55: =IF($A55="","",MIN(1,$G55*Assumptions!$E$17)) | V55: =IF($A55="","",$C55*U55*(1-(1-T55)^MIN(1,$D55))/(1+$E55)^MIN(1,$D55)) | W55: =IF($A55="","",$C55*U55*(IF(OR($H55=0,T55=0),0,T55/(1+$E55)*(1-((1-T55)/(1+$E55))^$H55)/(1-(1-T55)/(1+$E55)))+(1-T55)^$H55*(1-(1-T55)^$I55)/(1+$E55)^$D55)) | X55: =IF($A55="","",IF($B55=3,$C55*U55,IF($B55=2,W55,V55))) | Y55: =IF($A55="","",L55*Assumptions!$C$15+Q55*Assumptions!$C$16+V55*Assumptions!$C$17) | Z55: =IF($A55="","",M55*Assumptions!$C$15+R55*Assumptions!$C$16+W55*Assumptions!$C$17) | AA55: =IF($A55="","",N55*Assumptions!$C$15+S55*Assumptions!$C$16+X55*Assumptions!$C$17) | AB55: =IF($A55="","",IF(C55=0,0,AA55/C55))
A57: Total | C57: =SUM(C6:C55) -> 41504500 | L57: =SUM(L6:L55) -> 945625.39 | M57: =SUM(M6:M55) -> 1042188.1 | N57: =SUM(N6:N55) -> 1104154.5 | Q57: =SUM(Q6:Q55) -> 718740.95 | R57: =SUM(R6:R55) -> 845724.49 | S57: =SUM(S6:S55) -> 1018352.4 | V57: =SUM(V6:V55) -> 1143698.6 | W57: =SUM(W6:W55) -> 1319731.3 | X57: =SUM(X6:X55) -> 1380097.5 | Y57: =SUM(Y6:Y55) -> 959670.47 | Z57: =SUM(Z6:Z55) -> 1086158.4 | AA57: =SUM(AA6:AA55) -> 1169777 | AB57: =IF(C57=0,0,AA57/C57) -> 0.028184341

Sheet Summary
B1: ECL Summary
B2: ="Reporting date: "&TEXT(Assumptions!C3,"dd-mmm-yyyy")&" | Currency: "&Assumptions!C4 -> Reporting date: 30-Sep-2026 | Currency: USD
B4: ECL by stage
B5: Segment | C5: # Sukuk | D5: EAD | E5: ECL allowance | F5: Coverage
B6: 1 | C6: =COUNTIFS(Portfolio!$W$6:$W$55,B6) -> 4 | D6: =SUMIFS(Portfolio!$Q$6:$Q$55,Portfolio!$W$6:$W$55,B6) -> 26246500 | E6: =SUMIFS(Portfolio!$Z$6:$Z$55,Portfolio!$W$6:$W$55,B6) -> 7793.191 | F6: =IF(D6=0,0,E6/D6) -> 0.00029692306 | G6: Stage 1 - 12-month ECL
B7: 2 | C7: =COUNTIFS(Portfolio!$W$6:$W$55,B7) -> 3 | D7: =SUMIFS(Portfolio!$Q$6:$Q$55,Portfolio!$W$6:$W$55,B7) -> 13688000 | E7: =SUMIFS(Portfolio!$Z$6:$Z$55,Portfolio!$W$6:$W$55,B7) -> 187013.81 | F7: =IF(D7=0,0,E7/D7) -> 0.01366261 | G7: Stage 2 - lifetime ECL (SICR)
B8: 3 | C8: =COUNTIFS(Portfolio!$W$6:$W$55,B8) -> 1 | D8: =SUMIFS(Portfolio!$Q$6:$Q$55,Portfolio!$W$6:$W$55,B8) -> 1570000 | E8: =SUMIFS(Portfolio!$Z$6:$Z$55,Portfolio!$W$6:$W$55,B8) -> 974970 | F8: =IF(D8=0,0,E8/D8) -> 0.621 | G8: Stage 3 - credit-impaired
B9: Total | C9: =SUM(C6:C8) -> 8 | D9: =SUM(D6:D8) -> 41504500 | E9: =SUM(E6:E8) -> 1169777 | F9: =IF(D9=0,0,E9/D9) -> 0.028184341
B12: ECL by sukuk structure
B13: Segment | C13: # Sukuk | D13: EAD | E13: ECL allowance | F13: Coverage
B14: Sovereign | C14: =COUNTIFS(Portfolio!$D$6:$D$55,B14) -> 2 | D14: =SUMIFS(Portfolio!$Q$6:$Q$55,Portfolio!$D$6:$D$55,B14) -> 18189000 | E14: =SUMIFS(Portfolio!$Z$6:$Z$55,Portfolio!$D$6:$D$55,B14) -> 2979.0868 | F14: =IF(D14=0,0,E14/D14) -> 0.00016378508
B15: Ijara (asset-backed) | C15: =COUNTIFS(Portfolio!$D$6:$D$55,B15) -> 1 | D15: =SUMIFS(Portfolio!$Q$6:$Q$55,Portfolio!$D$6:$D$55,B15) -> 7590000 | E15: =SUMIFS(Portfolio!$Z$6:$Z$55,Portfolio!$D$6:$D$55,B15) -> 62098.8 | F15: =IF(D15=0,0,E15/D15) -> 0.00818166
B16: Ijara (asset-based) | C16: =COUNTIFS(Portfolio!$D$6:$D$55,B16) -> 1 | D16: =SUMIFS(Portfolio!$Q$6:$Q$55,Portfolio!$D$6:$D$55,B16) -> 4038000 | E16: =SUMIFS(Portfolio!$Z$6:$Z$55,Portfolio!$D$6:$D$55,B16) -> 30194.106 | F16: =IF(D16=0,0,E16/D16) -> 0.0074774903
B17: Wakala | C17: =COUNTIFS(Portfolio!$D$6:$D$55,B17) -> 1 | D17: =SUMIFS(Portfolio!$Q$6:$Q$55,Portfolio!$D$6:$D$55,B17) -> 5042000 | E17: =SUMIFS(Portfolio!$Z$6:$Z$55,Portfolio!$D$6:$D$55,B17) -> 3895.0888 | F17: =IF(D17=0,0,E17/D17) -> 0.00077252852
B18: Murabaha | C18: =COUNTIFS(Portfolio!$D$6:$D$55,B18) -> 1 | D18: =SUMIFS(Portfolio!$Q$6:$Q$55,Portfolio!$D$6:$D$55,B18) -> 3015500 | E18: =SUMIFS(Portfolio!$Z$6:$Z$55,Portfolio!$D$6:$D$55,B18) -> 919.01539 | F18: =IF(D18=0,0,E18/D18) -> 0.00030476385
B19: Mudaraba | C19: =COUNTIFS(Portfolio!$D$6:$D$55,B19) -> 1 | D19: =SUMIFS(Portfolio!$Q$6:$Q$55,Portfolio!$D$6:$D$55,B19) -> 1570000 | E19: =SUMIFS(Portfolio!$Z$6:$Z$55,Portfolio!$D$6:$D$55,B19) -> 974970 | F19: =IF(D19=0,0,E19/D19) -> 0.621
B20: Musharaka | C20: =COUNTIFS(Portfolio!$D$6:$D$55,B20) -> 1 | D20: =SUMIFS(Portfolio!$Q$6:$Q$55,Portfolio!$D$6:$D$55,B20) -> 2060000 | E20: =SUMIFS(Portfolio!$Z$6:$Z$55,Portfolio!$D$6:$D$55,B20) -> 94720.905 | F20: =IF(D20=0,0,E20/D20) -> 0.045981022
B21: Total | C21: =SUM(C14:C20) -> 8 | D21: =SUM(D14:D20) -> 41504500 | E21: =SUM(E14:E20) -> 1169777 | F21: =IF(D21=0,0,E21/D21) -> 0.028184341
B24: ECL by accounting classification
B25: Segment | C25: # Sukuk | D25: EAD | E25: ECL allowance | F25: Coverage
B26: AC | C26: =COUNTIFS(Portfolio!$E$6:$E$55,B26) -> 6 | D26: =SUMIFS(Portfolio!$Q$6:$Q$55,Portfolio!$E$6:$E$55,B26) -> 32424500 | E26: =SUMIFS(Portfolio!$Z$6:$Z$55,Portfolio!$E$6:$E$55,B26) -> 1135687.8 | F26: =IF(D26=0,0,E26/D26) -> 0.035025607 | G26: Allowance deducted from carrying amount
B27: FVOCI | C27: =COUNTIFS(Portfolio!$E$6:$E$55,B27) -> 2 | D27: =SUMIFS(Portfolio!$Q$6:$Q$55,Portfolio!$E$6:$E$55,B27) -> 9080000 | E27: =SUMIFS(Portfolio!$Z$6:$Z$55,Portfolio!$E$6:$E$55,B27) -> 34089.195 | F27: =IF(D27=0,0,E27/D27) -> 0.0037543166 | G27: Allowance recognised in OCI (not netted)
B28: Total | C28: =SUM(C26:C27) -> 8 | D28: =SUM(D26:D27) -> 41504500 | E28: =SUM(E26:E27) -> 1169777 | F28: =IF(D28=0,0,E28/D28) -> 0.028184341
B31: Scenario sensitivity (100% weight on each scenario)
B32: Scenario | C32: Weight | E32: ECL allowance | F32: vs weighted
B33: =Assumptions!B15 -> Base | C33: =Assumptions!C15 -> 0.5 | E33: =ECL_Calc!N57 -> 1104154.5 | F33: =IF($E$36=0,0,E33/$E$36-1) -> -0.056098279
B34: =Assumptions!B16 -> Upside | C34: =Assumptions!C16 -> 0.2 | E34: =ECL_Calc!S57 -> 1018352.4 | F34: =IF($E$36=0,0,E34/$E$36-1) -> -0.1294474
B35: =Assumptions!B17 -> Downside | C35: =Assumptions!C17 -> 0.3 | E35: =ECL_Calc!X57 -> 1380097.5 | F35: =IF($E$36=0,0,E35/$E$36-1) -> 0.1797954
B36: Probability-weighted | C36: =SUM(C33:C35) -> 1 | E36: =ECL_Calc!AA57 -> 1169777
B39: Model integrity checks
B40: Check | C40: Result | F40: Status
B41: Scenario weights sum to 100% | C41: =Assumptions!C18 -> 1 | F41: =IF(ROUND(C41,6)=1,"OK","ERROR") -> OK
B42: Rows with unknown rating | C42: =SUMPRODUCT((Portfolio!$A$6:$A$55<>"")*ISNA(Portfolio!$T$6:$T$55))+SUMPRODUCT((Portfolio!$A$6:$A$55<>"")*ISNA(Portfolio!$S$6:$S$55)) -> 0 | F42: =IF(C42=0,"OK","ERROR") -> OK
